Workbook

Sheet Ventas Mensuales
A1: VENTAS MENSUALES – PRODUCTOS MÉDICOS DIÁLISIS
A2: Davita / Fresenius | 2020 – 2024 | Unidades vendidas por mes
A4: Año | B4: Mes | C4: Mes# | D4: DV-001 Concentrado Bicarbonato Diálisis 9.45L (Litros) | E4: DV-002 Dializador FX80 Alto Flujo (Unidades) | F4: DV-003 Catéter Doble Lumen Mahurkar 11.5Fr (Unidades) | G4: DV-004 Solución Peritoneal Dianeal 2L 1.5% (Bolsas) | H4: DV-005 Agujas Fístula AVF 15G x 25mm (caja x100) (Cajas)
A5: 2020 | B5: Ene | C5: 1 | D5: 10796 | E5: 2846 | F5: 679 | G5: 5214 | H5: 1005
A6: 2020 | B6: Feb | C6: 2 | D6: 10488 | E6: 3162 | F6: 635 | G6: 5204 | H6: 865
A7: 2020 | B7: Mar | C7: 3 | D7: 10887 | E7: 3328 | F7: 702 | G7: 5606 | H7: 1070
A8: 2020 | B8: Abr | C8: 4 | D8: 11845 | E8: 3277 | F8: 795 | G8: 6377 | H8: 993
A9: 2020 | B9: May | C9: 5 | D9: 12839 | E9: 3683 | F9: 795 | G9: 5975 | H9: 1204
A10: 2020 | B10: Jun | C10: 6 | D10: 12271 | E10: 3436 | F10: 786 | G10: 6872 | H10: 1174
A11: 2020 | B11: Jul | C11: 7 | D11: 13597 | E11: 3919 | F11: 869 | G11: 7203 | H11: 1165
A12: 2020 | B12: Ago | C12: 8 | D12: 13310 | E12: 4053 | F12: 897 | G12: 7215 | H12: 1225
A13: 2020 | B13: Sep | C13: 9 | D13: 13136 | E13: 3440 | F13: 811 | G13: 6351 | H13: 1088
A14: 2020 | B14: Oct | C14: 10 | D14: 11717 | E14: 3342 | F14: 787 | G14: 6461 | H14: 1098
A15: 2020 | B15: Nov | C15: 11 | D15: 11516 | E15: 3271 | F15: 755 | G15: 6500 | H15: 1104
A16: 2020 | B16: Dic | C16: 12 | D16: 12576 | E16: 3415 | F16: 854 | G16: 6042 | H16: 1111
... A64: 2024 | B64: Dic | C64: 12 | D64: 13459 | E64: 3848 | F64: 820 | G64: 6428 | H64: 1299
A65: TOTAL | D65: =SUM(D5:D64) -> 772713 | E65: =SUM(E5:E64) -> 224122 | F65: =SUM(F5:F64) -> 51235 | G65: =SUM(G5:G64) -> 398425 | H65: =SUM(H5:H64) -> 70363

Sheet Hoja1
B1: DV-001 Concentrado Bicarbonato Diálisis 9.45L (Litros) | C1: Tendencia | D1: Estacionalidad | E1: Forecast | K1: Año 2020 | L1: Año 2021 | M1: Año 2022 | N1: Año 2023 | O1: Año 2024 | Q1: Año 2020 | R1: Año 2021 | S1: Año 2022 | T1: Año 2023 | U1: Año 2024 | V1: Estacionalidad
A2: 43831 | B2: 10796 | C2: =+$G$2+$G$3*A2 -> 12047.306 | D2: =+V2 -> 0.90676089 | E2: =+C2*D2 -> 10924.026 | F2: ß0 | G2: =+INTERCEPT(B2:B61,A2:A61) -> -28541.936 | J2: enero | K2: =+B2 -> 10796 | L2: =+B14 -> 12184 | M2: =+B26 -> 11994 | N2: =+B38 -> 12151 | O2: =+B50 -> 11257 | Q2: =+K2/K$15 -> 0.89359765 | R2: =+L2/L$15 -> 0.95042708 | S2: =+M2/M$15 -> 0.92929919 | T2: =+N2/N$15 -> 0.90507995 | U2: =+O2/O$15 -> 0.85540055 | V2: =+AVERAGE(Q2:U2) -> 0.90676089
A3: 43862 | B3: 10488 | C3: =+$G$2+$G$3*A3 -> 12076.013 | D3: =+V3 -> 0.85638638 | E3: =+C3*D3 -> 10341.733 | F3: ß1 | G3: =+SLOPE(B2:B61,A2:A61) -> 0.92603962 | J3: febrero | K3: =+B3 -> 10488 | L3: =+B15 -> 11396 | M3: =+B27 -> 10805 | N3: =+B39 -> 11031 | O3: =+B51 -> 11397 | Q3: =+K3/K$15 -> 0.86810413 | R3: =+L3/L$15 -> 0.88895823 | S3: =+M3/M$15 -> 0.83717507 | T3: =+N3/N$15 -> 0.82165558 | U3: =+O3/O$15 -> 0.86603892 | V3: =+AVERAGE(Q3:U3) -> 0.85638638
A4: 43891 | B4: 10887 | C4: =+$G$2+$G$3*A4 -> 12102.868 | D4: =+V4 -> 0.91611747 | E4: =+C4*D4 -> 11087.649 | J4: marzo | K4: =+B4 -> 10887 | L4: =+B16 -> 11634 | M4: =+B28 -> 12043 | N4: =+B40 -> 12496 | O4: =+B52 -> 11950 | Q4: =+K4/K$15 -> 0.90112983 | R4: =+L4/L$15 -> 0.90752369 | S4: =+M4/M$15 -> 0.93309573 | T4: =+N4/N$15 -> 0.93077763 | U4: =+O4/O$15 -> 0.90806046 | V4: =+AVERAGE(Q4:U4) -> 0.91611747
A5: 43922 | B5: 11845 | C5: =+$G$2+$G$3*A5 -> 12131.576 | D5: =+V5 -> 1.0013591 | E5: =+C5*D5 -> 12148.064 | J5: abril | K5: =+B5 -> 11845 | L5: =+B17 -> 12373 | M5: =+B29 -> 12790 | N5: =+B41 -> 13808 | O5: =+B53 -> 13709 | Q5: =+K5/K$15 -> 0.98042462 | R5: =+L5/L$15 -> 0.96517025 | S5: =+M5/M$15 -> 0.99097354 | T5: =+N5/N$15 -> 1.0285033 | U5: =+O5/O$15 -> 1.0417239 | V5: =+AVERAGE(Q5:U5) -> 1.0013591
A6: 43952 | B6: 12839 | C6: =+$G$2+$G$3*A6 -> 12159.357 | D6: =+V6 -> 1.0555293 | E6: =+C6*D6 -> 12834.557 | J6: mayo | K6: =+B6 -> 12839 | L6: =+B18 -> 13225 | M6: =+B30 -> 13289 | N6: =+B42 -> 14606 | O6: =+B54 -> 14025 | Q6: =+K6/K$15 -> 1.0626992 | R6: =+L6/L$15 -> 1.0316315 | S6: =+M6/M$15 -> 1.0296362 | T6: =+N6/N$15 -> 1.0879432 | U6: =+O6/O$15 -> 1.0657362 | V6: =+AVERAGE(Q6:U6) -> 1.0555293
A7: 43983 | B7: 12271 | C7: =+$G$2+$G$3*A7 -> 12188.064 | D7: =+V7 -> 1.0193937 | E7: =+C7*D7 -> 12424.436 | J7: junio | K7: =+B7 -> 12271 | L7: =+B19 -> 12877 | M7: =+B31 -> 13101 | N7: =+B43 -> 13345 | O7: =+B55 -> 14051 | Q7: =+K7/K$15 -> 1.0156851 | R7: =+L7/L$15 -> 1.0044854 | S7: =+M7/M$15 -> 1.0150699 | T7: =+N7/N$15 -> 0.99401629 | U7: =+O7/O$15 -> 1.0677119 | V7: =+AVERAGE(Q7:U7) -> 1.0193937
A8: 44013 | B8: 13597 | C8: =+$G$2+$G$3*A8 -> 12215.845 | D8: =+V8 -> 1.0939365 | E8: =+C8*D8 -> 13363.359 | J8: julio | K8: =+B8 -> 13597 | L8: =+B20 -> 13001 | M8: =+B32 -> 15246 | N8: =+B44 -> 13845 | O8: =+B56 -> 14707 | Q8: =+K8/K$15 -> 1.1254397 | R8: =+L8/L$15 -> 1.0141581 | S8: =+M8/M$15 -> 1.1812653 | T8: =+N8/N$15 -> 1.0312593 | U8: =+O8/O$15 -> 1.1175603 | V8: =+AVERAGE(Q8:U8) -> 1.0939365
A9: 44044 | B9: 13310 | C9: =+$G$2+$G$3*A9 -> 12244.552 | D9: =+V9 -> 1.0885396 | E9: =+C9*D9 -> 13328.68 | J9: agosto | K9: =+B9 -> 13310 | L9: =+B21 -> 13856 | M9: =+B33 -> 13754 | N9: =+B45 -> 15813 | O9: =+B57 -> 13379 | Q9: =+K9/K$15 -> 1.1016844 | R9: =+L9/L$15 -> 1.0808534 | S9: =+M9/M$15 -> 1.0656646 | T9: =+N9/N$15 -> 1.1778478 | U9: =+O9/O$15 -> 1.0166478 | V9: =+AVERAGE(Q9:U9) -> 1.0885396
A10: 44075 | B10: 13136 | C10: =+$G$2+$G$3*A10 -> 12273.26 | D10: =+V10 -> 1.0554657 | E10: =+C10*D10 -> 12954.004 | J10: septiembre | K10: =+B10 -> 13136 | L10: =+B22 -> 12547 | M10: =+B34 -> 12913 | N10: =+B46 -> 15178 | O10: =+B58 -> 14216 | Q10: =+K10/K$15 -> 1.0872822 | R10: =+L10/L$15 -> 0.97874332 | S10: =+M10/M$15 -> 1.0005036 | T10: =+N10/N$15 -> 1.1305492 | U10: =+O10/O$15 -> 1.08025 | V10: =+AVERAGE(Q10:U10) -> 1.0554657
A11: 44105 | B11: 11717 | C11: =+$G$2+$G$3*A11 -> 12301.041 | D11: =+V11 -> 1.014509 | E11: =+C11*D11 -> 12479.517 | J11: octubre | K11: =+B11 -> 11717 | L11: =+B23 -> 13392 | M11: =+B35 -> 12426 | N11: =+B47 -> 13769 | O11: =+B59 -> 14077 | Q11: =+K11/K$15 -> 0.96982991 | R11: =+L11/L$15 -> 1.0446585 | S11: =+M11/M$15 -> 0.9627707 | T11: =+N11/N$15 -> 1.0255984 | U11: =+O11/O$15 -> 1.0696876 | V11: =+AVERAGE(Q11:U11) -> 1.014509
A12: 44136 | B12: 11516 | C12: =+$G$2+$G$3*A12 -> 12329.748 | D12: =+V12 -> 0.97033552 | E12: =+C12*D12 -> 11963.992 | J12: noviembre | K12: =+B12 -> 11516 | L12: =+B24 -> 13340 | M12: =+B36 -> 13712 | N12: =+B48 -> 12177 | O12: =+B60 -> 11692 | Q12: =+K12/K$15 -> 0.9531929 | R12: =+L12/L$15 -> 1.0406022 | S12: =+M12/M$15 -> 1.0624104 | T12: =+N12/N$15 -> 0.90701659 | U12: =+O12/O$15 -> 0.88845547 | V12: =+AVERAGE(Q12:U12) -> 0.97033552
A13: 44166 | B13: 12576 | C13: =+$G$2+$G$3*A13 -> 12357.529 | D13: =+V13 -> 1.0216668 | E13: =+C13*D13 -> 12625.277 | J13: diciembre | K13: =+B13 -> 12576 | L13: =+B25 -> 14009 | M13: =+B37 -> 12805 | N13: =+B49 -> 12885 | O13: =+B61 -> 13459 | Q13: =+K13/K$15 -> 1.0409303 | R13: =+L13/L$15 -> 1.0927883 | S13: =+M13/M$15 -> 0.99213575 | T13: =+N13/N$15 -> 0.95975271 | U13: =+O13/O$15 -> 1.0227268 | V13: =+AVERAGE(Q13:U13) -> 1.0216668
A14: 44197 | B14: 12184 | C14: =+$G$2+$G$3*A14 -> 12386.236 | D14: =+D2 -> 0.90676089 | E14: =+C14*D14 -> 11231.355
A15: 44228 | B15: 11396 | C15: =+$G$2+$G$3*A15 -> 12414.944 | D15: =+D3 -> 0.85638638 | E15: =+C15*D15 -> 10631.989 | J15: Promedio | K15: =+AVERAGE(K2:K13) -> 12081.5 | L15: =+AVERAGE(L2:L13) -> 12819.5 | M15: =+AVERAGE(M2:M13) -> 12906.5 | N15: =+AVERAGE(N2:N13) -> 13425.333 | O15: =+AVERAGE(O2:O13) -> 13159.917
A16: 44256 | B16: 11634 | C16: =+$G$2+$G$3*A16 -> 12440.873 | D16: =+D4 -> 0.91611747 | E16: =+C16*D16 -> 11397.301
A17: 44287 | B17: 12373 | C17: =+$G$2+$G$3*A17 -> 12469.58 | D17: =+D5 -> 1.0013591 | E17: =+C17*D17 -> 12486.528
A18: 44317 | B18: 13225 | C18: =+$G$2+$G$3*A18 -> 12497.361 | D18: =+D6 -> 1.0555293 | E18: =+C18*D18 -> 13191.33
A19: 44348 | B19: 12877 | C19: =+$G$2+$G$3*A19 -> 12526.068 | D19: =+D7 -> 1.0193937 | E19: =+C19*D19 -> 12768.996
A20: 44378 | B20: 13001 | C20: =+$G$2+$G$3*A20 -> 12553.85 | D20: =+D8 -> 1.0939365 | E20: =+C20*D20 -> 13733.115
A21: 44409 | B21: 13856 | C21: =+$G$2+$G$3*A21 -> 12582.557 | D21: =+D9 -> 1.0885396 | E21: =+C21*D21 -> 13696.611
A22: 44440 | B22: 12547 | C22: =+$G$2+$G$3*A22 -> 12611.264 | D22: =+D10 -> 1.0554657 | E22: =+C22*D22 -> 13310.756
A23: 44470 | B23: 13392 | C23: =+$G$2+$G$3*A23 -> 12639.045 | D23: =+D11 -> 1.014509 | E23: =+C23*D23 -> 12822.426
A24: 44501 | B24: 13340 | C24: =+$G$2+$G$3*A24 -> 12667.753 | D24: =+D12 -> 0.97033552 | E24: =+C24*D24 -> 12291.97
A25: 44531 | B25: 14009 | C25: =+$G$2+$G$3*A25 -> 12695.534 | D25: =+D13 -> 1.0216668 | E25: =+C25*D25 -> 12970.605
A26: 44562 | B26: 11994 | C26: =+$G$2+$G$3*A26 -> 12724.241 | D26: =+D14 -> 0.90676089 | E26: =+C26*D26 -> 11537.844
A27: 44593 | B27: 10805 | C27: =+$G$2+$G$3*A27 -> 12752.948 | D27: =+D15 -> 0.85638638 | E27: =+C27*D27 -> 10921.451
... A61: 45627 | B61: 13459 | C61: =+$G$2+$G$3*A61 -> 13710.473 | D61: =+D49 -> 1.0216668 | E61: =+C61*D61 -> 14007.535
A62: 45658 | C62: =+$G$2+$G$3*A62 -> 13739.18 | D62: =+D50 -> 0.90676089 | E62: =+C62*D62 -> 12458.151
A63: 45689 | C63: =+$G$2+$G$3*A63 -> 13767.888 | D63: =+D51 -> 0.85638638 | E63: =+C63*D63 -> 11790.631
A64: 45717 | C64: =+$G$2+$G$3*A64 -> 13793.817 | D64: =+D52 -> 0.91611747 | E64: =+C64*D64 -> 12636.756
A65: 45748 | C65: =+$G$2+$G$3*A65 -> 13822.524 | D65: =+D53 -> 1.0013591 | E65: =+C65*D65 -> 13841.311
A66: 45778 | C66: =+$G$2+$G$3*A66 -> 13850.305 | D66: =+D54 -> 1.0555293 | E66: =+C66*D66 -> 14619.402
A67: 45809 | C67: =+$G$2+$G$3*A67 -> 13879.012 | D67: =+D55 -> 1.0193937 | E67: =+C67*D67 -> 14148.178
A68: 45839 | C68: =+$G$2+$G$3*A68 -> 13906.794 | D68: =+D56 -> 1.0939365 | E68: =+C68*D68 -> 15213.15
A69: 45870 | C69: =+$G$2+$G$3*A69 -> 13935.501 | D69: =+D57 -> 1.0885396 | E69: =+C69*D69 -> 15169.344
A70: 45901 | C70: =+$G$2+$G$3*A70 -> 13964.208 | D70: =+D58 -> 1.0554657 | E70: =+C70*D70 -> 14738.742
A71: 45931 | C71: =+$G$2+$G$3*A71 -> 13991.989 | D71: =+D59 -> 1.014509 | E71: =+C71*D71 -> 14194.999
A72: 45962 | C72: =+$G$2+$G$3*A72 -> 14020.696 | D72: =+D60 -> 0.97033552 | E72: =+C72*D72 -> 13604.78
A73: 45992 | C73: =+$G$2+$G$3*A73 -> 14048.478 | D73: =+D61 -> 1.0216668 | E73: =+C73*D73 -> 14352.863
...

Sheet Ingresos USD
A1: INGRESOS MENSUALES (USD) – PRODUCTOS MÉDICOS DIÁLISIS
A2: Davita / Fresenius | 2020 – 2024 | Ingresos en USD
A4: Año | B4: Mes | C4: Mes# | D4: DV-001 Concentrado Bicarbonato Diálisis 9.45L (USD) | E4: DV-002 Dializador FX80 Alto Flujo (USD) | F4: DV-003 Catéter Doble Lumen Mahurkar 11.5Fr (USD) | G4: DV-004 Solución Peritoneal Dianeal 2L 1.5% (USD) | H4: DV-005 Agujas Fístula AVF 15G x 25mm (caja x100) (USD)
A5: 2020 | B5: Ene | C5: 1 | D5: ='Ventas Mensuales'!D5*4.8 -> 51820.8 | E5: ='Ventas Mensuales'!E5*38.5 -> 109571 | F5: ='Ventas Mensuales'!F5*95 -> 64505 | G5: ='Ventas Mensuales'!G5*12.3 -> 64132.2 | H5: ='Ventas Mensuales'!H5*48 -> 48240
A6: 2020 | B6: Feb | C6: 2 | D6: ='Ventas Mensuales'!D6*4.8 -> 50342.4 | E6: ='Ventas Mensuales'!E6*38.5 -> 121737 | F6: ='Ventas Mensuales'!F6*95 -> 60325 | G6: ='Ventas Mensuales'!G6*12.3 -> 64009.2 | H6: ='Ventas Mensuales'!H6*48 -> 41520
A7: 2020 | B7: Mar | C7: 3 | D7: ='Ventas Mensuales'!D7*4.8 -> 52257.6 | E7: ='Ventas Mensuales'!E7*38.5 -> 128128 | F7: ='Ventas Mensuales'!F7*95 -> 66690 | G7: ='Ventas Mensuales'!G7*12.3 -> 68953.8 | H7: ='Ventas Mensuales'!H7*48 -> 51360
A8: 2020 | B8: Abr | C8: 4 | D8: ='Ventas Mensuales'!D8*4.8 -> 56856 | E8: ='Ventas Mensuales'!E8*38.5 -> 126164.5 | F8: ='Ventas Mensuales'!F8*95 -> 75525 | G8: ='Ventas Mensuales'!G8*12.3 -> 78437.1 | H8: ='Ventas Mensuales'!H8*48 -> 47664
A9: 2020 | B9: May | C9: 5 | D9: ='Ventas Mensuales'!D9*4.8 -> 61627.2 | E9: ='Ventas Mensuales'!E9*38.5 -> 141795.5 | F9: ='Ventas Mensuales'!F9*95 -> 75525 | G9: ='Ventas Mensuales'!G9*12.3 -> 73492.5 | H9: ='Ventas Mensuales'!H9*48 -> 57792
A10: 2020 | B10: Jun | C10: 6 | D10: ='Ventas Mensuales'!D10*4.8 -> 58900.8 | E10: ='Ventas Mensuales'!E10*38.5 -> 132286 | F10: ='Ventas Mensuales'!F10*95 -> 74670 | G10: ='Ventas Mensuales'!G10*12.3 -> 84525.6 | H10: ='Ventas Mensuales'!H10*48 -> 56352
A11: 2020 | B11: Jul | C11: 7 | D11: ='Ventas Mensuales'!D11*4.8 -> 65265.6 | E11: ='Ventas Mensuales'!E11*38.5 -> 150881.5 | F11: ='Ventas Mensuales'!F11*95 -> 82555 | G11: ='Ventas Mensuales'!G11*12.3 -> 88596.9 | H11: ='Ventas Mensuales'!H11*48 -> 55920
A12: 2020 | B12: Ago | C12: 8 | D12: ='Ventas Mensuales'!D12*4.8 -> 63888 | E12: ='Ventas Mensuales'!E12*38.5 -> 156040.5 | F12: ='Ventas Mensuales'!F12*95 -> 85215 | G12: ='Ventas Mensuales'!G12*12.3 -> 88744.5 | H12: ='Ventas Mensuales'!H12*48 -> 58800
A13: 2020 | B13: Sep | C13: 9 | D13: ='Ventas Mensuales'!D13*4.8 -> 63052.8 | E13: ='Ventas Mensuales'!E13*38.5 -> 132440 | F13: ='Ventas Mensuales'!F13*95 -> 77045 | G13: ='Ventas Mensuales'!G13*12.3 -> 78117.3 | H13: ='Ventas Mensuales'!H13*48 -> 52224
A14: 2020 | B14: Oct | C14: 10 | D14: ='Ventas Mensuales'!D14*4.8 -> 56241.6 | E14: ='Ventas Mensuales'!E14*38.5 -> 128667 | F14: ='Ventas Mensuales'!F14*95 -> 74765 | G14: ='Ventas Mensuales'!G14*12.3 -> 79470.3 | H14: ='Ventas Mensuales'!H14*48 -> 52704
A15: 2020 | B15: Nov | C15: 11 | D15: ='Ventas Mensuales'!D15*4.8 -> 55276.8 | E15: ='Ventas Mensuales'!E15*38.5 -> 125933.5 | F15: ='Ventas Mensuales'!F15*95 -> 71725 | G15: ='Ventas Mensuales'!G15*12.3 -> 79950 | H15: ='Ventas Mensuales'!H15*48 -> 52992
A16: 2020 | B16: Dic | C16: 12 | D16: ='Ventas Mensuales'!D16*4.8 -> 60364.8 | E16: ='Ventas Mensuales'!E16*38.5 -> 131477.5 | F16: ='Ventas Mensuales'!F16*95 -> 81130 | G16: ='Ventas Mensuales'!G16*12.3 -> 74316.6 | H16: ='Ventas Mensuales'!H16*48 -> 53328
... A64: 2024 | B64: Dic | C64: 12 | D64: ='Ventas Mensuales'!D64*4.8 -> 64603.2 | E64: ='Ventas Mensuales'!E64*38.5 -> 148148 | F64: ='Ventas Mensuales'!F64*95 -> 77900 | G64: ='Ventas Mensuales'!G64*12.3 -> 79064.4 | H64: ='Ventas Mensuales'!H64*48 -> 62352
A65: TOTAL | D65: =SUM(D5:D64) -> 3709022.4 | E65: =SUM(E5:E64) -> 8628697 | F65: =SUM(F5:F64) -> 4867325 | G65: =SUM(G5:G64) -> 4900627.5 | H65: =SUM(H5:H64) -> 3377424

Sheet Resumen Anual
A1: RESUMEN ANUAL DE VENTAS – UNIDADES E INGRESOS
A2: Davita / Fresenius | 2020 – 2024
A4: Producto | B4: 2020 Uds | C4: 2020 USD | D4: 2021 Uds | E4: 2021 USD | F4: 2022 Uds | G4: 2022 USD | H4: 2023 Uds | I4: 2023 USD | J4: 2024 Uds | K4: 2024 USD | L4: TOTAL Uds | M4: TOTAL USD
A5: DV-001 – Concentrado Bicarbonato Diálisis 9.45L | B5: =SUM('Ventas Mensuales'!D5:D16) -> 144978 | C5: =SUM('Ingresos USD'!D5:D16) -> 695894.4 | D5: =SUM('Ventas Mensuales'!D17:D28) -> 153834 | E5: =SUM('Ingresos USD'!D17:D28) -> 738403.2 | F5: =SUM('Ventas Mensuales'!D29:D40) -> 154878 | G5: =SUM('Ingresos USD'!D29:D40) -> 743414.4 | H5: =SUM('Ventas Mensuales'!D41:D52) -> 161104 | I5: =SUM('Ingresos USD'!D41:D52) -> 773299.2 | J5: =SUM('Ventas Mensuales'!D53:D64) -> 157919 | K5: =SUM('Ingresos USD'!D53:D64) -> 758011.2 | L5: =B5+D5+F5+H5+J5 -> 772713 | M5: =C5+E5+G5+I5+K5 -> 3709022.4
A6: DV-002 – Dializador FX80 Alto Flujo | B6: =SUM('Ventas Mensuales'!E5:E16) -> 41172 | C6: =SUM('Ingresos USD'!E5:E16) -> 1585122 | D6: =SUM('Ventas Mensuales'!E17:E28) -> 45588 | E6: =SUM('Ingresos USD'!E17:E28) -> 1755138 | F6: =SUM('Ventas Mensuales'!E29:E40) -> 44794 | G6: =SUM('Ingresos USD'!E29:E40) -> 1724569 | H6: =SUM('Ventas Mensuales'!E41:E52) -> 47354 | I6: =SUM('Ingresos USD'!E41:E52) -> 1823129 | J6: =SUM('Ventas Mensuales'!E53:E64) -> 45214 | K6: =SUM('Ingresos USD'!E53:E64) -> 1740739 | L6: =B6+D6+F6+H6+J6 -> 224122 | M6: =C6+E6+G6+I6+K6 -> 8628697
A7: DV-003 – Catéter Doble Lumen Mahurkar 11.5Fr | B7: =SUM('Ventas Mensuales'!F5:F16) -> 9365 | C7: =SUM('Ingresos USD'!F5:F16) -> 889675 | D7: =SUM('Ventas Mensuales'!F17:F28) -> 10365 | E7: =SUM('Ingresos USD'!F17:F28) -> 984675 | F7: =SUM('Ventas Mensuales'!F29:F40) -> 10609 | G7: =SUM('Ingresos USD'!F29:F40) -> 1007855 | H7: =SUM('Ventas Mensuales'!F41:F52) -> 10636 | I7: =SUM('Ingresos USD'!F41:F52) -> 1010420 | J7: =SUM('Ventas Mensuales'!F53:F64) -> 10260 | K7: =SUM('Ingresos USD'!F53:F64) -> 974700 | L7: =B7+D7+F7+H7+J7 -> 51235 | M7: =C7+E7+G7+I7+K7 -> 4867325
A8: DV-004 – Solución Peritoneal Dianeal 2L 1.5% | B8: =SUM('Ventas Mensuales'!G5:G16) -> 75020 | C8: =SUM('Ingresos USD'!G5:G16) -> 922746 | D8: =SUM('Ventas Mensuales'!G17:G28) -> 79393 | E8: =SUM('Ingresos USD'!G17:G28) -> 976533.9 | F8: =SUM('Ventas Mensuales'!G29:G40) -> 82351 | G8: =SUM('Ingresos USD'!G29:G40) -> 1012917.3 | H8: =SUM('Ventas Mensuales'!G41:G52) -> 82063 | I8: =SUM('Ingresos USD'!G41:G52) -> 1009374.9 | J8: =SUM('Ventas Mensuales'!G53:G64) -> 79598 | K8: =SUM('Ingresos USD'!G53:G64) -> 979055.4 | L8: =B8+D8+F8+H8+J8 -> 398425 | M8: =C8+E8+G8+I8+K8 -> 4900627.5
A9: DV-005 – Agujas Fístula AVF 15G x 25mm (caja x100) | B9: =SUM('Ventas Mensuales'!H5:H16) -> 13102 | C9: =SUM('Ingresos USD'!H5:H16) -> 628896 | D9: =SUM('Ventas Mensuales'!H17:H28) -> 14051 | E9: =SUM('Ingresos USD'!H17:H28) -> 674448 | F9: =SUM('Ventas Mensuales'!H29:H40) -> 14074 | G9: =SUM('Ingresos USD'!H29:H40) -> 675552 | H9: =SUM('Ventas Mensuales'!H41:H52) -> 14804 | I9: =SUM('Ingresos USD'!H41:H52) -> 710592 | J9: =SUM('Ventas Mensuales'!H53:H64) -> 14332 | K9: =SUM('Ingresos USD'!H53:H64) -> 687936 | L9: =B9+D9+F9+H9+J9 -> 70363 | M9: =C9+E9+G9+I9+K9 -> 3377424
A10: TOTAL GENERAL | B10: =SUM(B5:B9) -> 283637 | C10: =SUM(C5:C9) -> 4722333.4 | D10: =SUM(D5:D9) -> 303231 | E10: =SUM(E5:E9) -> 5129198.1 | F10: =SUM(F5:F9) -> 306706 | G10: =SUM(G5:G9) -> 5164307.7 | H10: =SUM(H5:H9) -> 315961 | I10: =SUM(I5:I9) -> 5326815.1 | ... M10: =SUM(M5:M9) -> 25483096

Sheet Catálogo
A1: CATÁLOGO DE PRODUCTOS – PRECIOS UNITARIOS
A3: Código | B3: Descripción | C3: Proveedor | D3: Unidad | E3: Precio Unit. (USD) | F3: Notas
A4: DV-001 | B4: Concentrado Bicarbonato Diálisis 9.45L | C4: Davita | D4: Litros | E4: 4.8 | F4: Concentrado ácido para hemodiálisis bicarbonato
A5: DV-002 | B5: Dializador FX80 Alto Flujo | C5: Fresenius | D5: Unidades | E5: 38.5 | F5: Membrana polisulfona, esterilización por vapor
A6: DV-003 | B6: Catéter Doble Lumen Mahurkar 11.5Fr | C6: Davita | D6: Unidades | E6: 95 | F6: Acceso vascular temporal; longitud 20cm
A7: DV-004 | B7: Solución Peritoneal Dianeal 2L 1.5% | C7: Fresenius | D7: Bolsas | E7: 12.3 | F7: Diálisis peritoneal ambulatoria continua (CAPD)
A8: DV-005 | B8: Agujas Fístula AVF 15G x 25mm (caja x100) | C8: Fresenius | D8: Cajas | E8: 48 | F8: Aguja tipo Lancet, bisel corto, 100 uds/caja
